Workbook

Sheet Theory
A1: Forecasting & Scenario Analysis: Theory & Frameworks
A3: 1. Budget vs Forecast: Key Differences
A4: Dimension | B4: Budget | C4: Forecast
A5: Definition | B5: Annual financial plan & target | C5: Updated projection of future performance
A6: Purpose | B6: Goal-setting, resource allocation, accountability | C6: Planning tool, early warning system, decision support
A7: Time Horizon | B7: Fixed 12 months (fiscal year) | C7: Rolling 12-18+ months, continuous
A8: Update Frequency | B8: Once per year | C8: Monthly or quarterly
A9: Flexibility | B9: Static, rarely changed mid-year | C9: Dynamic, adjusted for new information
A10: Accuracy | B10: Less accurate (made far in advance) | C10: More accurate (incorporates actuals)
A11: Detail Level | B11: Highly detailed by department | C11: Can be high-level or detailed
A12: Accountability | B12: Performance measurement, bonuses tied to budget | C12: Planning only, not performance evaluation
A14: 2. What is a Rolling Forecast?
A15: Definition:
A16: A rolling forecast is a continuous projection that extends a fixed period into the future (typically 12-18 months) and is updated regularly (monthly or quarterly). As each period ends, a new period is added to maintain the forward-looking horizon.
A18: How It Works:
A19: Example: In January 2026, you forecast through December 2026 (12 months ahead)
A20: In February 2026, you forecast through January 2026 (still 12 months ahead)
A21: In March 2026, you forecast through February 2026 (always 12 months ahead)
A22: This 'rolling' approach ensures you always have visibility into the next 12 months
A24: Key Benefits:
A25: • Continuous planning - no year-end cliff
A26: • Incorporates actual results and trends as they emerge
A27: • Enables proactive decision-making vs reactive
... A37: Scenario planning involves creating multiple forecast versions based on different assumptions to prepare for various possible futures. The standard framework uses three scenarios:
A39: Scenario Type | B39: Description | C39: Typical Use
A40: Best Case (Upside) | B40: Optimistic assumptions - everything goes right. Higher revenue growth, lower costs, favorable market conditions. | C40: Prepare for growth: hiring plans, capacity expansion, inventory buildup
A41: Base Case (Most Likely) | B41: Realistic assumptions - most probable outcome based on current trends and known factors. | C41: Primary planning scenario: budget allocation, performance targets, guidance to stakeholders
A42: Worst Case (Downside) | B42: Pessimistic assumptions - challenges emerge. Lower revenue, higher costs, adverse market conditions. | C42: Risk mitigation: cost reduction plans, cash preservation, contingency planning
A44: Key Assumptions to Scenario Plan:
A45: • Revenue growth rates (market demand, competition, pricing)
A46: • Customer acquisition and retention (churn rates, CAC)
A47: • Cost structure (COGS margins, operating leverage)
A48: • Macroeconomic factors (interest rates, inflation, FX rates)
A49: • Operational factors (headcount, productivity, capacity utilization)
A51: 4. Sensitivity Analysis
A52: Definition:
A53: Sensitivity analysis tests how changes in key assumptions (input variables) impact financial outcomes (output metrics like revenue, EBITDA, cash flow). Identifies which drivers have the greatest impact.
A55: Process:
A56: 1. Identify key value drivers (revenue growth rate, gross margin, OpEx ratio)
A57: 2. Define reasonable range for each driver (+/- 10%, +/- 20%, etc.)
...

Sheet Exercise
A1: Build a 12-Month Rolling Forecast
A2: Task: You are the FP&A Analyst at TechFlow Inc. It's March 2026. Build a rolling forecast for Apr 2026 - Mar 2026
A4: Context & Current Situation
A5: • Today is March 31, 2026. You have actuals for Jan-Mar 2026.
A6: • Original FY2026 budget was created in December 2026 (before the year started).
A7: • Q1 performance shows you're trending behind budget on revenue but ahead on cost control.
A8: • You need to update the forecast for the remaining 9 months (Apr-Dec 2026) plus add Q1 2026 (Jan-Mar 2026).
A10: Q1 2026 Actuals (Jan-Mar)
A11: Line Item | B11: Jan 2026 | C11: Feb 2026 | D11: Mar 2026 | E11: Q1 Total
A12: Revenue | B12: 279724.03 | C12: 310806.46 | D12: 321359.3 | E12: =SUM(B12:D12) -> 911889.79
A13: Cost of Goods Sold | B13: 80338.45 | C13: 90624.71 | D13: 91850.45 | E13: =SUM(B13:D13) -> 262813.61
A14: Gross Profit | B14: 218057.64 | C14: 185983.81 | D14: 240378.2 | E14: =SUM(B14:D14) -> 644419.65
A15: Gross Margin % | B15: =B14/B12 -> 0.77954561 | C15: =C14/C12 -> 0.59839107 | D15: =D14/D12 -> 0.74800449 | E15: =E14/E12 -> 0.70668589
A16: Operating Expenses | B16: 222021.16 | C16: 211032.46 | D16: 250489.58 | E16: =SUM(B16:D16) -> 683543.2
A17: Sales & Marketing | B17: 100525.89 | C17: 104011.47 | D17: 112612.22 | E17: =SUM(B17:D17) -> 317149.58
A18: Research & Development | B18: 86043.75 | C18: 90656.5 | D18: 83783.82 | E18: =SUM(B18:D18) -> 260484.07
A19: General & Administrative | B19: 38539.52 | C19: 39318.82 | D19: 36501.12 | E19: =SUM(B19:D19) -> 114359.46
A20: EBITDA | B20: -25526.85 | C20: -18275.36 | D20: -12369.38 | E20: =SUM(B20:D20) -> -56171.59
A22: Original FY2026 Budget (for comparison)
A23: The budget assumed 5% monthly revenue growth and 68% gross margin. Q1 actuals show slower growth but better margin control.
A25: Budget Line Item | B25: Q1 Budget | C25: Full Year Budget
A26: Revenue | B26: 909704.56 | C26: 3827931.5
A27: Gross Margin % | B27: 0.7 | C27: 0.64
A28: EBITDA | B28: -13893.42 | C28: 163707.86
A30: Build Rolling Forecast (Apr 2026 - Mar 2027)
A31: Complete the table below using these updated assumptions:
A33: Updated Assumptions (as of Mar 31, 2026):
A34: Assumption | B34: Value | C34: Notes
A35: Revenue Growth Rate (Apr-Dec 2026) | B35: 0.04 | C35: 4% monthly (revised down from budget)
A36: Revenue Growth Rate (Jan-Mar 2026) | B36: 0.06 | C36: 6% monthly (expecting acceleration)
A37: Gross Margin % | B37: 0.71 | C37: Maintain Q1 performance
A38: S&M % of Revenue | B38: 0.33 | C38: (cost control initiative)
A39: R&D | B39: 85155.13 | C39: (continued investment)
A40: G&A | B40: 39255.69 | C40: (fixed costs)
A42: Rolling Forecast Template (Complete the shaded cells)
A43: Line Item | B43: 46113 | C43: 46143 | D43: 46174 | E43: 46204 | F43: 46235 | G43: 46266 | H43: 46296 | I43: 46327 | J43: 46357 | K43: 46388 | L43: 46419 | M43: 46447 | N43: 12M Total
A44: Revenue | B44: =D12*(1+B35) -> 334213.67 | C44: =B44*(1+$B$35) -> 347582.22 | D44: =C44*(1+$B$35) -> 361485.51 | E44: =D44*(1+$B$35) -> 375944.93 | F44: =E44*(1+$B$35) -> 390982.73 | G44: =F44*(1+$B$35) -> 406622.03 | H44: =G44*(1+$B$35) -> 422886.92 | I44: =H44*(1+$B$35) -> 439802.39 | J44: =I44*(1+$B$35) -> 457394.49 | K44: =J44*(1+$B$36) -> 484838.16 | L44: =K44*(1+$B$36) -> 513928.45 | M44: =L44*(1+$B$36) -> 544764.15 | N44: =SUM(B44:M44) -> 5080445.6
A45: Cost of Goods Sold | B45: =B44-B46 -> 96921.965 | C45: =C44-C46 -> 100798.84 | D45: =D44-D46 -> 104830.8 | E45: =E44-E46 -> 109024.03 | F45: =F44-F46 -> 113384.99 | G45: =G44-G46 -> 117920.39 | H45: =H44-H46 -> 122637.21 | I45: =I44-I46 -> 127542.69 | ... M45: =M44-M46 -> 157981.6 | N45: =SUM(B45:M45) -> 1473329.2
A46: Gross Profit | B46: =B44*$B$37 -> 237291.71 | C46: =C44*$B$37 -> 246783.38 | D46: =D44*$B$37 -> 256654.71 | E46: =E44*$B$37 -> 266920.9 | F46: =F44*$B$37 -> 277597.73 | G46: =G44*$B$37 -> 288701.64 | H46: =H44*$B$37 -> 300249.71 | I46: =I44*$B$37 -> 312259.7 | ... M46: =M44*$B$37 -> 386782.55 | N46: =SUM(B46:M46) -> 3607116.4
A47: Gross Margin % | B47: =B46/B44 -> 0.71 | C47: =C46/C44 -> 0.71 | D47: =D46/D44 -> 0.71 | E47: =E46/E44 -> 0.71 | F47: =F46/F44 -> 0.71 | G47: =G46/G44 -> 0.71 | H47: =H46/H44 -> 0.71 | I47: =I46/I44 -> 0.71 | ... N47: =N46/N44 -> 0.71
...

Sheet Solution
A1: Completed 12-Month Rolling Forecast with Analysis
A3: Q1 2026 Actuals (Reference)
A4: Line Item | B4: Jan 2026 | C4: Feb 2026 | D4: Mar 2026 | E4: Q1 Total | F4: =D5 -> 321359.3
A5: Revenue | B5: =Exercise!B12 -> 279724.03 | C5: =Exercise!C12 -> 310806.46 | D5: =Exercise!D12 -> 321359.3 | E5: =Exercise!E12 -> 911889.79 | F5: =D5*4% -> 12854.372
A6: Gross Margin % | B6: =Exercise!B15 -> 0.77954561 | C6: =Exercise!C15 -> 0.59839107 | D6: =Exercise!D15 -> 0.74800449 | E6: =Exercise!E15 -> 0.70668589 | F6: =SUM(F4:F5) -> 334213.67
A7: EBITDA | B7: =Exercise!B20 -> -25526.85 | C7: =Exercise!C20 -> -18275.36 | D7: =Exercise!D20 -> -12369.38 | E7: =Exercise!E20 -> -56171.59
A9: Rolling Forecast (Apr 2026 - Mar 2026) with Formulas
A10: Line Item | B10: =Exercise!B43 -> 46113 | C10: =Exercise!C43 -> 46143 | D10: =Exercise!D43 -> 46174 | E10: =Exercise!E43 -> 46204 | F10: =Exercise!F43 -> 46235 | G10: =Exercise!G43 -> 46266 | H10: =Exercise!H43 -> 46296 | I10: =Exercise!I43 -> 46327 | ... M10: =Exercise!M43 -> 46447 | N10: 12M Total
A11: Revenue | B11: =D5*(1+Exercise!B35) -> 334213.67 | C11: =B11*(1+Exercise!$B$35) -> 347582.22 | D11: =C11*(1+Exercise!$B$35) -> 361485.51 | E11: =D11*(1+Exercise!$B$35) -> 375944.93 | F11: =E11*(1+Exercise!$B$35) -> 390982.73 | G11: =F11*(1+Exercise!$B$35) -> 406622.03 | H11: =G11*(1+Exercise!$B$35) -> 422886.92 | I11: =H11*(1+Exercise!$B$35) -> 439802.39 | J11: =I11*(1+Exercise!$B$35) -> 457394.49 | K11: =J11*(1+Exercise!$B$36) -> 484838.16 | L11: =K11*(1+Exercise!$B$36) -> 513928.45 | M11: =L11*(1+Exercise!$B$36) -> 544764.15 | N11: =SUM(B11:M11) -> 5080445.6
A12: Cost of Goods Sold | B12: =B11*(1-Exercise!$B$37) -> 96921.965 | C12: =C11*(1-Exercise!$B$37) -> 100798.84 | D12: =D11*(1-Exercise!$B$37) -> 104830.8 | E12: =E11*(1-Exercise!$B$37) -> 109024.03 | F12: =F11*(1-Exercise!$B$37) -> 113384.99 | G12: =G11*(1-Exercise!$B$37) -> 117920.39 | H12: =H11*(1-Exercise!$B$37) -> 122637.21 | I12: =I11*(1-Exercise!$B$37) -> 127542.69 | ... M12: =M11*(1-Exercise!$B$37) -> 157981.6 | N12: =SUM(B12:M12) -> 1473329.2
A13: Gross Profit | B13: =B11-B12 -> 237291.71 | C13: =C11-C12 -> 246783.38 | D13: =D11-D12 -> 256654.71 | E13: =E11-E12 -> 266920.9 | F13: =F11-F12 -> 277597.73 | G13: =G11-G12 -> 288701.64 | H13: =H11-H12 -> 300249.71 | I13: =I11-I12 -> 312259.7 | ... M13: =M11-M12 -> 386782.55 | N13: =SUM(B13:M13) -> 3607116.4
A14: Gross Margin % | B14: =B13/B11 -> 0.71 | C14: =C13/C11 -> 0.71 | D14: =D13/D11 -> 0.71 | E14: =E13/E11 -> 0.71 | F14: =F13/F11 -> 0.71 | G14: =G13/G11 -> 0.71 | H14: =H13/H11 -> 0.71 | I14: =I13/I11 -> 0.71 | ... N14: =N13/N11 -> 0.71
A15: Operating Expenses:
A16: Sales & Marketing | B16: =Exercise!$B$38*Solution!B11 -> 110290.51 | C16: =Exercise!$B$38*Solution!C11 -> 114702.13 | D16: =Exercise!$B$38*Solution!D11 -> 119290.22 | E16: =Exercise!$B$38*Solution!E11 -> 124061.83 | F16: =Exercise!$B$38*Solution!F11 -> 129024.3 | G16: =Exercise!$B$38*Solution!G11 -> 134185.27 | H16: =Exercise!$B$38*Solution!H11 -> 139552.68 | I16: =Exercise!$B$38*Solution!I11 -> 145134.79 | ... M16: =Exercise!$B$38*Solution!M11 -> 179772.17 | N16: =SUM(B16:M16) -> 1676547.1
A17: Research & Development | B17: =Exercise!$B$39 -> 85155.13 | C17: =Exercise!$B$39 -> 85155.13 | D17: =Exercise!$B$39 -> 85155.13 | E17: =Exercise!$B$39 -> 85155.13 | F17: =Exercise!$B$39 -> 85155.13 | G17: =Exercise!$B$39 -> 85155.13 | H17: =Exercise!$B$39 -> 85155.13 | I17: =Exercise!$B$39 -> 85155.13 | ... M17: =Exercise!$B$39 -> 85155.13 | N17: =SUM(B17:M17) -> 1021861.6
A18: General & Administrative | B18: =Exercise!$B$40 -> 39255.69 | C18: =Exercise!$B$40 -> 39255.69 | D18: =Exercise!$B$40 -> 39255.69 | E18: =Exercise!$B$40 -> 39255.69 | F18: =Exercise!$B$40 -> 39255.69 | G18: =Exercise!$B$40 -> 39255.69 | H18: =Exercise!$B$40 -> 39255.69 | I18: =Exercise!$B$40 -> 39255.69 | ... M18: =Exercise!$B$40 -> 39255.69 | N18: =SUM(B18:M18) -> 471068.28
A19: Total Operating Expenses | B19: =SUM(B16:B18) -> 234701.33 | C19: =SUM(C16:C18) -> 239112.95 | D19: =SUM(D16:D18) -> 243701.04 | E19: =SUM(E16:E18) -> 248472.65 | F19: =SUM(F16:F18) -> 253435.12 | G19: =SUM(G16:G18) -> 258596.09 | H19: =SUM(H16:H18) -> 263963.5 | I19: =SUM(I16:I18) -> 269545.61 | ... N19: =SUM(N16:N18) -> 3169476.9
A20: EBITDA | B20: =B13-B19 -> 2590.3754 | C20: =C13-C19 -> 7670.4232 | D20: =D13-D19 -> 12953.673 | E20: =E13-E19 -> 18448.253 | F20: =F13-F19 -> 24162.616 | G20: =G13-G19 -> 30105.553 | H20: =H13-H19 -> 36286.208 | I20: =I13-I19 -> 42714.089 | ... N20: =N13-N19 -> 437639.5
A21: EBITDA Margin % | B21: =B20/B11 -> 0.0077506565 | C21: =C20/C11 -> 0.022067939 | D21: =D20/D11 -> 0.035834557 | E21: =E20/E11 -> 0.049071689 | F21: =F20/F11 -> 0.061799701 | G21: =G20/G11 -> 0.074038174 | H21: =H20/H11 -> 0.085805937 | I21: =I20/I11 -> 0.097121093 | ... N21: =N20/N11 -> 0.086141952
A23: Variance Analysis: Forecast vs Original Budget
A24: Metric | B24: Original FY2026 Budget | C24: Rolling 12M Forecast | D24: Variance ($) | E24: Variance (pp)
A25: Revenue | B25: =Exercise!C26 -> 3827931.5 | C25: =N11 -> 5080445.6 | D25: =C25-B25 -> 1252514.2 | E25: =D25/B25 -> 0.32720392
A26: EBITDA | B26: =Exercise!C28 -> 163707.86 | C26: =N20 -> 437639.5 | D26: =C26-B26 -> 273931.64 | E26: =D26/B26 -> 1.6732956
A27: EBITDA Margin % | B27: =B26/B25 -> 0.042766664 | C27: =C26/C25 -> 0.086141952 | D27: =C27-B27 -> 0.043375287 | E27: =D27 -> 0.043375287
A29: Key Insights & Commentary
A30: 1. Revenue Trajectory:
A31: The rolling 12-month forecast (Apr 2026 – Mar 2026) projects $4.87M in revenue, which is $672K (+16%) HIGHER than the original FY2026 full-year budget of $4.2M. However, this comparison is not apples-to-apples: the budget covers Jan–Dec 2026 while the rolling forecast covers Apr 2026–Mar 2026, which includes three additional Q1 2026 months growing at 5%. On a comparable basis (Apr–Dec 2026 only), the forecast of $3.41M is modestly ahead of the implied budget remainder of $3.32M (+$97K, +3%) — reflecting slower-than-budgeted monthly growth (4% vs 5%) offset by a stronger-than-expected Q1 actuals base.
A33: 2. Profitability Timeline:
A34: EBITDA turns positive starting Jul-25 and improves steadily through Mar-26. EBITDA Margin improves from -3.3% in Apr-25 to 11.6% by Mar-26. Rolling 12-month EBITDA totals $242k, compared to budgeted EBITDA of $150k. This indicates the business is expected to cross operating breakeven mid-year and achieve increasing operating leverage as revenue scales.
A36: 3. Operating Leverage:
A37: With 70% gross margin and operating expenses growing at a slower pace than revenue, operating leverage is clearly visible. Gross profit grows faster than operating expenses. EBITDA margin expands by ~15 percentage points across the forecast horizon. This suggests the company’s cost structure is scalable, assuming expense discipline is maintained.
A39: 4. Key Assumptions & Risks:
A40: • Revenue growth rate (4% then 5%): Risk if market deteriorates further
A41: • Gross margin maintenance at 70%: Dependent on pricing power and COGS control
A42: • Sales & Marketing grows in line with revenue
A43: • R&D and G&A largely fixed, supporting margin expansion
... A50: 5. Implement monthly reforecasting: Update the rolling forecast each month as actuals come in
